Workbook

Sheet Instructions
A1: Hand check: sites and merged records
A2: Yellow cells are yours to fill in; everything else is generated.
A4: Base URL
B5: Type the site's address here, without a trailing slash (e.g. https://beta.example.org). Every link in the workbook starts with it; left empty, links are relative paths (/sites/..., /proposals/...).
A7: Progress (updates as you fill in)
A8: Sites answered | B8: =COUNTA(Sites!E2:E51)&" of 50" -> 0 of 50
A9: Sites answered No | B9: =COUNTIF(Sites!E2:E51,"No") -> 0
A10: Sites: share of Yes/No answers that are No (unweighted) | B10: =IFERROR(COUNTIF(Sites!E2:E51,"No")/(COUNTIF(Sites!E2:E51,"Yes")+COUNTIF(Sites!E2:E51,"No")),"")
A11: Merged records answered | B11: =COUNTA('Merged records'!E2:E2)&" of 0" -> 0 of 0
A12: Merged records answered 'No (several projects)' | B12: =COUNTIF('Merged records'!E2:E2,"No (several projects)") -> 0
A13: Merged: share of Yes/No answers that are No (unweighted) | B13: =IFERROR(COUNTIF('Merged records'!E2:E2,"No (several projects)")/(COUNTIF('Merged records'!E2:E2,"Yes")+COUNTIF('Merged records'!E2:E2,"No (several projects)")),"")
A16: What this is for
A17: Purpose | B17: You are checking a sample of how the platform groups filings. Two questions decide two things for the beta: (1) do the records in a site belong to one project or site? If more than about 1 in 10 sites group records that are not the same project, sites are switched off for the beta (SITES_ENABLED=0). (2) Is each merged record one real project? If many are several projects, merged records need splitting before the site can claim 'one record per project'.
A18: Time | B18: About 2 to 3 hours in all: 50 sites and 0 merged records. Most rows take 1 to 2 minutes; the 5 largest sites can take 5 to 10 minutes each (their unit lists are long). You can stop and resume: blank rows are simply not counted.
A19: What to fill in | B19: Only the yellow cells on the Sites and Merged records sheets: the two dropdown columns and Notes. Everything else is the platform's own data as a public visitor sees it. 'Site members' and 'Merged links' list every member and source link in full, for reference.
A21: How to check a site (Sites sheet)
A22: Read the row | B22: 'Members' lists the records in the site in display order: #1 is the lead (the largest active filing). Each line gives the name, register, MW, technology, status, and how the platform labels it relative to the lead, with its confidence. Units of one EIA plant are indented under the plant's first record; long unit lists are summarised. Open the site link to see the page itself.
A23: All these belong to one project or site? | B23: Yes: every record belongs to one project or one physical site (phases, units, co-located technologies, re-filings and expansions of one site all count as belonging). No: at least one record does not belong with the others (a different developer's project, a competing request at the same substation, an unrelated building). Unsure: you cannot tell from public information.
A24: If no, what is wrong | B24: When you answer No, pick the main problem. 'Unrelated record grouped' is the one the 1-in-10 rule counts (as do 'Other' and a No with nothing picked). 'Missing record' (a record that should be in the site is not), 'Wrong lead' and 'Wrong label' are recorded as quality issues of a site whose members do belong together; you may also pick them on a Yes row. Use Notes for anything else.
A26: How to check a merged record (Merged records sheet)
A27: Read the row | B27: 'Source links' lists each register row the platform merged into this one record: register, the name the register uses, MW, technology, status and the register's own id. The record link opens the record page, which shows the same members.
A28: One real project? | B28: Yes: all the source rows describe one real project. No (several projects): they describe two or more projects, phases or plants that should be separate records (they may still sit in one site). Unsure: you cannot tell.
A29: What kind | B29: When the answer is No, what the rows are: phases of one development; separate units or plants at one site; a re-filing or replacement of the same project; unrelated projects; or other.
A31: How the result is used
A32: Scoring | B32: Run: python -m services.sites.handcheck score <this file>. It reports the share of sites judged No (grouping errors) with a 95 % Wilson interval, the same share weighted back to every served site (the sample over-represents the riskier groupings, so the weighted figure is the one that answers 'how many sites are wrong'), and the merged-record share judged 'several projects', by category. Unsure and blank rows are left out of the shares and reported.
A33: The 1-in-10 rule | B33: Sites are switched off for the beta when the weighted estimate of sites grouping unrelated records is above 10 %. The scorer states both the point estimate and the interval's lower bound: above 10 % on the point estimate meets the rule as stated; a lower bound above 10 % means the sample rules out an acceptable rate.
A34: What a result will mean | B34: With 50 sites judged (unweighted, before weighting): 0 wrong gives an interval of 0 to 7.1%, so the rule is clearly met; up to 0 wrong keeps the whole interval at or under 10 %; 6 or more wrong puts the point estimate above 10 %; 10 or more wrong puts even the lower bound above 10 %. 5 wrong (exactly 1 in 10) gives 4.3% to 21.4%: 50 items cannot separate 8 % from 12 %, only clean results from clearly bad ones.
A36: Labels you will see
A37: LEAD | B37: The site's headline record: the largest filing that is not withdrawn, ties to the latest.
A38: unit of #n | B38: Another generator of the same EIA plant as member #n (high confidence).
A39: phase of the lead | B39: Same project name, different phase or unit number.
A40: co-located with the lead | B40: A different technology at the same site (e.g. gas beside nuclear).
A41: expansion of / expanded by | B41: An addition to an operating plant, or a stated MW increase.
A42: superseded by / re-filing of | B42: A withdrawn filing that the lead replaced, or that came after it.
A43: same site, relation unclear | B43: Grouped by a shared identifier, but no rule says how they relate (low).
A44: Confidence | B44: high / medium / low is the rule's own strength, not a measured probability: this check is the first labelled sample.
A46: Example of a filled row (illustration only, not part of the sample)
A47: Sites example | B47: S00 | Example Ridge Solar | members: #1 Example Ridge Solar 200 MW; #2 Example Ridge Solar II 100 MW (phase of the lead, high); #3 Other Co Storage 50 MW (same site, relation unclear, low) | All these belong to one project or site? = No | If no, what is wrong = Unrelated record grouped | Notes = '#3 is a different developer's battery at the same substation'
A48: Merged example | B48: M00 | Example Flats | 1. CAISO queue: Example Flats I; 2. EIA-860M: Example Flats II | One real project? = No (several projects) | What kind = Phases of one development | Notes = 'two phases, separate EIA plants'
A50: About this file
...

Sheet Sites
A1: Item | B1: Site | C1: Grouped because | D1: Members (in site order) | E1: All these belong to one project or site? | F1: If no, what is wrong | G1: Notes | H1: Lead | I1: Members | J1: Lowest label confidence | K1: Connection points | L1: Sponsors | M1: EIA plant ids | N1: Stratum | O1: Stratum population | P1: Stratum sample | Q1: Weight | R1: Site id (this store) | S1: Member keys (stable)
A2: S01 | B2: =HYPERLINK(BaseURL&"/sites/site_1M4KNFAFTEBEAE4TDDHNH7F1S","Hashknife Energy Center II LLC") -> Hashknife Energy Center II LLC | C2: Same EIA plant | D2: #1 Hashknife Energy Center II LLC | EIA-860M Preliminary Monthly Electric Generator Inventory | 200 MW storage | Under construction | LEAD #2 Hashknife Energy Center II LLC | EIA-860M Preliminary Monthly Electric Generator Inventory | 200 MW solar | Under construction | unit of #1 (high) | H2: Hashknife Energy Center II LLC 200 MW, storage, Under construction, US-AZ | I2: 2 | J2: high | L2: Invenergy Services LLC | M2: 69779 | N2: eia_plant/high | O2: 320 | P2: 45 | Q2: =IF(P2>0,O2/P2,"") -> 7.1111111 | R2: site_1M4KNFAFTEBEAE4TDDHNH7F1S | S2: us.eia.860m:69779-HK2ST; us.eia.860m:69779-HK2SO
A3: S02 | B3: =HYPERLINK(BaseURL&"/sites/site_1M4KNFAG3FRT9CS6Y2S397JXZ","Rexford 2 Solar Farm") -> Rexford 2 Solar Farm | C3: Same EIA plant | D3: #1 Rexford 2 Solar Farm | EIA-860M Preliminary Monthly Electric Generator Inventory | 200 MW solar | Announced | LEAD #2 Rexford 2 Solar Farm | EIA-860M Preliminary Monthly Electric Generator Inventory | 200 MW storage | Announced | unit of #1 (high) | H3: Rexford 2 Solar Farm 200 MW, solar, Announced, US-CA | I3: 2 | J3: high | L3: 22SV 8ME LLC | M3: 68485 | N3: eia_plant/high | O3: 320 | P3: 45 | Q3: =IF(P3>0,O3/P3,"") -> 7.1111111 | R3: site_1M4KNFAG3FRT9CS6Y2S397JXZ | S3: us.eia.860m:68485-22SVA; us.eia.860m:68485-22SVB
A4: S03 | B4: =HYPERLINK(BaseURL&"/sites/site_1M4KNFAG1FTST2APWR06MHTV5","Harryoung PV and BESS") -> Harryoung PV and BESS | C4: Same EIA plant | D4: #1 Harryoung PV and BESS | EIA-860M Preliminary Monthly Electric Generator Inventory | 190 MW storage | Filed | LEAD #2 Harryoung PV and BESS | EIA-860M Preliminary Monthly Electric Generator Inventory | 190 MW solar | Filed | unit of #1 (high) | H4: Harryoung PV and BESS 190 MW, storage, Filed, US-TX | I4: 2 | J4: high | L4: Gransolar Texas Four LLC | M4: 67777 | N4: eia_plant/high | O4: 320 | P4: 45 | Q4: =IF(P4>0,O4/P4,"") -> 7.1111111 | R4: site_1M4KNFAG1FTST2APWR06MHTV5 | S4: us.eia.860m:67777-GRS4B; us.eia.860m:67777-GRS4P
A5: S04 | B5: =HYPERLINK(BaseURL&"/sites/site_1M4KNFAG6E9X8RCAC1X04VFZY","Energy Center") -> Energy Center | C5: Same EIA plant | D5: #1 Energy Center | EIA-860M Preliminary Monthly Electric Generator Inventory | 0.3 MW gas, combustion turbine | Announced | LEAD #2 Energy Center | EIA-860M Preliminary Monthly Electric Generator Inventory | 0.3 MW gas, combustion turbine | Announced | unit of #1 (high) #3 Energy Center | EIA-860M Preliminary Monthly Electric Generator Inventory | 0.3 MW gas, combustion turbine | Announced | unit of #1 (high) | H5: Energy Center 0.3 MW, gas, combustion turbine, Announced, US-CA | I5: 3 | J5: high | L5: University of Redlands | M5: 58168 | N5: eia_plant/high | O5: 320 | P5: 45 | Q5: =IF(P5>0,O5/P5,"") -> 7.1111111 | R5: site_1M4KNFAG6E9X8RCAC1X04VFZY | S5: us.eia.860m:58168-TURB4; us.eia.860m:58168-TURB6; us.eia.860m:58168-TURB5
A6: S05 | B6: =HYPERLINK(BaseURL&"/sites/site_1M4KNFAFTFVJSXDXM3DC3Z0QD","Snipatuit Road Solar") -> Snipatuit Road Solar | C6: Same EIA plant | D6: #1 Snipatuit Road Solar | EIA-860M Preliminary Monthly Electric Generator Inventory | 4 MW storage | Filed | LEAD #2 Snipatuit Road Solar | EIA-860M Preliminary Monthly Electric Generator Inventory | 4 MW solar | Filed | unit of #1 (high) | H6: Snipatuit Road Solar 4 MW, storage, Filed, US-MA | I6: 2 | J6: high | L6: Agilitas Energy, Inc. | M6: 68219 | N6: eia_plant/high | O6: 320 | P6: 45 | Q6: =IF(P6>0,O6/P6,"") -> 7.1111111 | R6: site_1M4KNFAFTFVJSXDXM3DC3Z0QD | S6: us.eia.860m:68219-SNIES; us.eia.860m:68219-SNIPV
A7: S06 | B7: =HYPERLINK(BaseURL&"/sites/site_1M4KNFAFZE4M94TQW52YA64S9","Libra Solar") -> Libra Solar | C7: Same EIA plant | D7: #1 Libra Solar | EIA-860M Preliminary Monthly Electric Generator Inventory | 700 MW storage | Under construction | LEAD #2 Libra Solar | EIA-860M Preliminary Monthly Electric Generator Inventory | 700 MW solar | Under construction | unit of #1 (high) | H7: Libra Solar 700 MW, storage, Under construction, US-NV | I7: 2 | J7: high | L7: Libra Solar LLC | M7: 69857 | N7: eia_plant/high | O7: 320 | P7: 45 | Q7: =IF(P7>0,O7/P7,"") -> 7.1111111 | R7: site_1M4KNFAFZE4M94TQW52YA64S9 | S7: us.eia.860m:69857-LBRBS; us.eia.860m:69857-LBRPV
A8: S07 | B8: =HYPERLINK(BaseURL&"/sites/site_1M4KNFAFWEC6TWT678BC3JDGJ","Project Matador Gas Plant (PMG)") -> Project Matador Gas Plant (PMG) | C8: Same EIA plant | D8: #1 Project Matador Gas Plant (PMG) | EIA-860M Preliminary Monthly Electric Generator Inventory | 260 MW gas, combined cycle | Announced | LEAD #2 Project Matador Gas Plant (PMG) | EIA-860M Preliminary Monthly Electric Generator Inventory | 260 MW gas, combined cycle | Announced | unit of #1 (high) #3 Project Matador Gas Plant (PMG) | EIA-860M Preliminary Monthly Electric Generator Inventory | 260 MW gas, combined cycle | Announced | unit of #1 (high) ... and 154 more units of EIA plant 69799 (unit of #1, high): 18.9 MW to 260 MW, Announced, Permitted; all listed on 'Site members' | H8: Project Matador Gas Plant (PMG) 260 MW, gas, combined cycle, Announced, US-TX | I8: 157 | J8: high | L8: Fermi America | M8: 69799 | N8: largest | O8: 5 | P8: 5 | Q8: =IF(P8>0,O8/P8,"") -> 1 | R8: site_1M4KNFAFWEC6TWT678BC3JDGJ | S8: us.eia.860m:69799-F1G01; us.eia.860m:69799-F1G02; us.eia.860m:69799-F1G03; us.eia.860m:69799-F2G01; us.eia.860m:69799-F2G02; us.eia.860m:69799-F2G03; us.eia.860m:69799-F1S02; us.eia.860m:69799-F1S01; us.eia.860m:69799-F1S03; us.eia.860m:69799-F2S02; us.eia.860m:69799-F2S01; us.eia.860m:69799-F2S03; us.eia.860m:69799-FBS01; us.eia.860m:69799-ES001; us.eia.860m:69799-ES002; us.eia.860m:69799-ES003; us.eia.860m:69799-ES004; us.eia.860m:69799-ES005; us.eia.860m:69799-ES006; us.eia.860m:69799-ES008; us.eia.860m:69799-ES007; us.eia.860m:69799-ES010; us.eia.860m:69799-ES009; us.eia.860m:69799-ES011; us.eia.860m:69799-ES012; us.eia.860m:69799-ES013; us.eia.860m:69799-ES014; us.eia.860m:69799-ES016; us.eia.860m:69799-ES015; us.eia.860m:69799-MS002; us.eia.860m:69799-MS001; us.eia.860m:69799-MS004; us.eia.860m:69799-MS003; us.eia.860m:69799-MS006; us.eia.860m:69799-MS005; us.eia.860m:69799-MS007; us.eia.860m:69799-MS009; us.eia.860m:69799-MS008; us.eia.860m:69799-MS012; us.eia.860m:69799-MS011; us.eia.860m:69799-MS010; us.eia.860m:69799-MS014; us.eia.860m:69799-MS013; us.eia.860m:69799-MS015; us.eia.860m:69799-MS016; us.eia.860m:69799-EG001; us.eia.860m:69799-EG002; us.eia.860m:69799-EG003; us.eia.860m:69799-EG004; us.eia.860m:69799-EG006; us.eia.860m:69799-EG005; us.eia.860m:69799-EG007; us.eia.860m:69799-EG008; us.eia.860m:69799-EG009; us.eia.860m:69799-EG010; us.eia.860m:69799-EG011; us.eia.860m:69799-EG013; us.eia.860m:69799-EG012; us.eia.860m:69799-EG014; us.eia.860m:69799-EG015; us.eia.860m:69799-EG017; us.eia.860m:69799-EG016; us.eia.860m:69799-EG019; us.eia.860m:69799-EG018; us.eia.860m:69799-EG020; us.eia.860m:69799-EG021; us.eia.860m:69799-EG022; us.eia.860m:69799-EG023; us.eia.860m:69799-EG025; us.eia.860m:69799-EG024; us.eia.860m:69799-EG028; us.eia.860m:69799-EG027; us.eia.860m:69799-EG026; us.eia.860m:69799-EG029; us.eia.860m:69799-EG030; us.eia.860m:69799-EG032; us.eia.860m:69799-EG031; us.eia.860m:69799-EG033; us.eia.860m:69799-EG034; us.eia.860m:69799-EG036; us.eia.860m:69799-EG035; us.eia.860m:69799-EG037; us.eia.860m:69799-EG038; us.eia.860m:69799-EG039; us.eia.860m:69799-EG040; us.eia.860m:69799-EG043; us.eia.860m:69799-EG041; us.eia.860m:69799-EG042; us.eia.860m:69799-EG044; us.eia.860m:69799-EG046; us.eia.860m:69799-EG045; us.eia.860m:69799-EG047; us.eia.860m:69799-EG048; us.eia.860m:69799-MG001; us.eia.860m:69799-MG002; us.eia.860m:69799-MG003; us.eia.860m:69799-MG004; us.eia.860m:69799-MG005; us.eia.860m:69799-MG006; us.eia.860m:69799-MG007; us.eia.860m:69799-MG008; us.eia.860m:69799-MG009; us.eia.860m:69799-MG010; us.eia.860m:69799-MG012; us.eia.860m:69799-MG011; us.eia.860m:69799-MG013; us.eia.860m:69799-MG015; us.eia.860m:69799-MG014; us.eia.860m:69799-MG017; us.eia.860m:69799-MG016; us.eia.860m:69799-MG019; us.eia.860m:69799-MG018; us.eia.860m:69799-MG021; us.eia.860m:69799-MG020; us.eia.860m:69799-MG022; us.eia.860m:69799-MG024; us.eia.860m:69799-MG023; us.eia.860m:69799-MG026; us.eia.860m:69799-MG025; us.eia.860m:69799-MG027; us.eia.860m:69799-MG028; us.eia.860m:69799-MG031; us.eia.860m:69799-MG030; us.eia.860m:69799-MG029; us.eia.860m:69799-MG033; us.eia.860m:69799-MG032; us.eia.860m:69799-MG034; us.eia.860m:69799-MG035; us.eia.860m:69799-MG036; us.eia.860m:69799-MG037; us.eia.860m:69799-MG038; us.eia.860m:69799-MG040; us.eia.860m:69799-MG039; us.eia.860m:69799-MG041; us.eia.860m:69799-MG042; us.eia.860m:69799-MG043; us.eia.860m:69799-MG044; us.eia.860m:69799-MG046; us.eia.860m:69799-MG045; us.eia.860m:69799-MG048; us.eia.860m:69799-MG047; us.eia.860m:69799-FBG01; us.eia.860m:69799-FBG04; us.eia.860m:69799-FBG03; us.eia.860m:69799-FBG02; us.eia.860m:69799-FBG06; us.eia.860m:69799-FBG05; us.eia.860m:69799-G6B01; us.eia.860m:69799-G6B03; us.eia.860m:69799-G6B02; us.eia.860m:69799-TM001; us.eia.860m:69799-TM003; us.eia.860m:69799-TM002; us.eia.860m:69799-TM005; us.eia.860m:69799-TM004; us.eia.860m:69799-TM006; us.eia.860m:69799-TM007
A9: S08 | B9: =HYPERLINK(BaseURL&"/sites/site_1M4KNFAG4E9Z80M5ZBWV2NS26","Red Butte Solar and Storage") -> Red Butte Solar and Storage | C9: Same EIA plant | D9: #1 Red Butte Solar and Storage | EIA-860M Preliminary Monthly Electric Generator Inventory | 300 MW solar | Filed | LEAD #2 Red Butte Solar and Storage | EIA-860M Preliminary Monthly Electric Generator Inventory | 300 MW storage | Filed | unit of #1 (high) | H9: Red Butte Solar and Storage 300 MW, solar, Filed, US-UT | I9: 2 | J9: high | L9: BrightNight Power | M9: 68371 | N9: eia_plant/high | O9: 320 | P9: 45 | Q9: =IF(P9>0,O9/P9,"") -> 7.1111111 | R9: site_1M4KNFAG4E9Z80M5ZBWV2NS26 | S9: us.eia.860m:68371-REBU; us.eia.860m:68371-REBU2
A10: S09 | B10: =HYPERLINK(BaseURL&"/sites/site_1M4KNFAFPE0F8HN6G5WMXRB9S","Bellefield 2 Solar & Energy Storage Farm") -> Bellefield 2 Solar & Energy Storage Farm | C10: Same EIA plant | D10: #1 Bellefield 2 Solar & Energy Storage Farm | EIA-860M Preliminary Monthly Electric Generator Inventory | 500 MW solar | Under construction | LEAD #2 Bellefield 2 Solar & Energy Storage Farm | EIA-860M Preliminary Monthly Electric Generator Inventory | 500 MW storage | Under construction | unit of #1 (high) | H10: Bellefield 2 Solar & Energy Storage Farm 500 MW, solar, Under construction, US-CA | I10: 2 | J10: high | L10: 26SB 8me LLC | M10: 64209 | N10: eia_plant/high | O10: 320 | P10: 45 | Q10: =IF(P10>0,O10/P10,"") -> 7.1111111 | R10: site_1M4KNFAFPE0F8HN6G5WMXRB9S | S10: us.eia.860m:64209-26SBA; us.eia.860m:64209-26SBB
A11: S10 | B11: =HYPERLINK(BaseURL&"/sites/site_1M4KNFAFSEBVT6M1ZKEPD6DWD","Randall Lane Solar") -> Randall Lane Solar | C11: Same EIA plant | D11: #1 Randall Lane Solar | EIA-860M Preliminary Monthly Electric Generator Inventory | 5 MW storage | Filed | LEAD #2 Randall Lane Solar | EIA-860M Preliminary Monthly Electric Generator Inventory | 5 MW solar | Filed | unit of #1 (high) | H11: Randall Lane Solar 5 MW, storage, Filed, US-MA | I11: 2 | J11: high | L11: ReWild Renewables, LLC | M11: 68218 | N11: eia_plant/high | O11: 320 | P11: 45 | Q11: =IF(P11>0,O11/P11,"") -> 7.1111111 | R11: site_1M4KNFAFSEBVT6M1ZKEPD6DWD | S11: us.eia.860m:68218-RANES; us.eia.860m:68218-RANPV
A12: S11 | B12: =HYPERLINK(BaseURL&"/sites/site_1M4KNFAG2EVA90M21PV4YS5WF","Traceview Advanced Power Station") -> Traceview Advanced Power Station | C12: Same EIA plant | D12: #1 Traceview Advanced Power Station | EIA-860M Preliminary Monthly Electric Generator Inventory | 477.7 MW gas, combined cycle | Under construction | LEAD #2 Traceview Advanced Power Station | EIA-860M Preliminary Monthly Electric Generator Inventory | 341.7 MW gas, combined cycle | Under construction | unit of #1 (high) | H12: Traceview Advanced Power Station 477.7 MW, gas, combined cycle, Under construction, US-MS | I12: 2 | J12: high | L12: Entergy Mississippi LLC | M12: 70187 | N12: eia_plant/high | O12: 320 | P12: 45 | Q12: =IF(P12>0,O12/P12,"") -> 7.1111111 | R12: site_1M4KNFAG2EVA90M21PV4YS5WF | S12: us.eia.860m:70187-CT1; us.eia.860m:70187-ST1
A13: S12 | B13: =HYPERLINK(BaseURL&"/sites/site_1M4KNFAFPEPPBQ2CEWW86TSTC","McGrau Ford Battery Storage Facility") -> McGrau Ford Battery Storage Facility | C13: Same EIA plant | D13: #1 McGrau Ford Battery Storage Facility | EIA-860M Preliminary Monthly Electric Generator Inventory | 265 MW storage | Under construction | LEAD #2 McGrau Ford Battery Storage Facility | EIA-860M Preliminary Monthly Electric Generator Inventory | 265 MW storage | Under construction | unit of #1 (high) | H13: McGrau Ford Battery Storage Facility 265 MW, storage, Under construction, US-GA | I13: 2 | J13: high | L13: Georgia Power Co | M13: 68512 | N13: eia_plant/high | O13: 320 | P13: 45 | Q13: =IF(P13>0,O13/P13,"") -> 7.1111111 | R13: site_1M4KNFAFPEPPBQ2CEWW86TSTC | S13: us.eia.860m:68512-1; us.eia.860m:68512-2
A14: S13 | B14: =HYPERLINK(BaseURL&"/sites/site_1M4KNFAFQEZMAPA7W30HF15FN","Horseshoe Lake") -> Horseshoe Lake | C14: Same EIA plant | D14: #1 Horseshoe Lake | EIA-860M Preliminary Monthly Electric Generator Inventory | 224 MW gas, combustion turbine | Under construction | LEAD #2 Horseshoe Lake | EIA-860M Preliminary Monthly Electric Generator Inventory | 224 MW gas, combustion turbine | Under construction | unit of #1 (high) #3 Horseshoe Lake | EIA-860M Preliminary Monthly Electric Generator Inventory | 224 MW gas, combustion turbine | Permitted | unit of #1 (high) #4 Horseshoe Lake | EIA-860M Preliminary Monthly Electric Generator Inventory | 224 MW gas, combustion turbine | Permitted | unit of #1 (high) | H14: Horseshoe Lake 224 MW, gas, combustion turbine, Under construction, US-OK | I14: 4 | J14: high | L14: Oklahoma Gas & Electric Co | M14: 2951 | N14: eia_plant/high | O14: 320 | P14: 45 | Q14: =IF(P14>0,O14/P14,"") -> 7.1111111 | R14: site_1M4KNFAFQEZMAPA7W30HF15FN | S14: us.eia.860m:2951-11; us.eia.860m:2951-12; us.eia.860m:2951-14; us.eia.860m:2951-13
A15: S14 | B15: =HYPERLINK(BaseURL&"/sites/site_1M4KNFAG4E5BRNSCVCX50FKJK","Dutchman Solar generation and BESS") -> Dutchman Solar generation and BESS | C15: Same EIA plant | D15: #1 Dutchman Solar generation and BESS | EIA-860M Preliminary Monthly Electric Generator Inventory | 499 MW solar | Filed | LEAD #2 Dutchman Solar generation and BESS | EIA-860M Preliminary Monthly Electric Generator Inventory | 499 MW storage | Filed | unit of #1 (high) | H15: Dutchman Solar generation and BESS 499 MW, solar, Filed, US-WY | I15: 2 | J15: high | L15: DUTC bn, LLC | M15: 68317 | N15: eia_plant/high | O15: 320 | P15: 45 | Q15: =IF(P15>0,O15/P15,"") -> 7.1111111 | R15: site_1M4KNFAG4E5BRNSCVCX50FKJK | S15: us.eia.860m:68317-DUTC1; us.eia.860m:68317-DUTC2
A16: S15 | B16: =HYPERLINK(BaseURL&"/sites/site_1M4KNFAG1FE7BK395V1BAGC82","Homer City Generating Station") -> Homer City Generating Station | C16: Same EIA plant | D16: #1 Homer City Generating Station | EIA-860M Preliminary Monthly Electric Generator Inventory | 360 MW gas, combined cycle | Announced | LEAD #2 Homer City Generating Station | EIA-860M Preliminary Monthly Electric Generator Inventory | 360 MW gas, combined cycle | Announced | unit of #1 (high) #3 Homer City Generating Station | EIA-860M Preliminary Monthly Electric Generator Inventory | 360 MW gas, combined cycle | Announced | unit of #1 (high) ... and 11 more units of EIA plant 3122 (unit of #1, high): 268 MW to 360 MW, Announced; all listed on 'Site members' | H16: Homer City Generating Station 360 MW, gas, combined cycle, Announced, US-PA | I16: 14 | J16: high | L16: Homer City Generation, L.P. | M16: 3122 | N16: largest | O16: 5 | P16: 5 | Q16: =IF(P16>0,O16/P16,"") -> 1 | R16: site_1M4KNFAG1FE7BK395V1BAGC82 | S16: us.eia.860m:3122-CT5; us.eia.860m:3122-CT6; us.eia.860m:3122-CT2; us.eia.860m:3122-CT3; us.eia.860m:3122-CT7; us.eia.860m:3122-CT4; us.eia.860m:3122-CT1; us.eia.860m:3122-CA5; us.eia.860m:3122-CA6; us.eia.860m:3122-CA2; us.eia.860m:3122-CA3; us.eia.860m:3122-CA7; us.eia.860m:3122-CA4; us.eia.860m:3122-CA1
A17: S16 | B17: =HYPERLINK(BaseURL&"/sites/site_1M4KNFAG7ER6SG5PA1BFHMD28","Colonel Charles D. Maynard Project") -> Colonel Charles D. Maynard Project | C17: Same EIA plant | D17: #1 Colonel Charles D. Maynard Project | EIA-860M Preliminary Monthly Electric Generator Inventory | 8.6 MW hydro | Filed | LEAD #2 Colonel Charles D. Maynard Project | EIA-860M Preliminary Monthly Electric Generator Inventory | 8.6 MW hydro | Filed | unit of #1 (high) #3 Colonel Charles D. Maynard Project | EIA-860M Preliminary Monthly Electric Generator Inventory | 8.6 MW hydro | Filed | unit of #1 (high) | H17: Colonel Charles D. Maynard Project 8.6 MW, hydro, Filed, US-AR | I17: 3 | J17: high | L17: Maynard Hydroelectric LLC | M17: 69695 | N17: eia_plant/high | O17: 320 | P17: 45 | Q17: =IF(P17>0,O17/P17,"") -> 7.1111111 | R17: site_1M4KNFAG7ER6SG5PA1BFHMD28 | S17: us.eia.860m:69695-CCM-1; us.eia.860m:69695-CCM-2; us.eia.860m:69695-CCM-3
A18: S17 | B18: =HYPERLINK(BaseURL&"/sites/site_1M4KNFAFRENZA5XJ93XNWENGA","CA Bloomington 2551 S Lilac Avenue Micro") -> CA Bloomington 2551 S Lilac Avenue Micro | C18: Same EIA plant | D18: #1 CA Bloomington 2551 S Lilac Avenue Micro | EIA-860M Preliminary Monthly Electric Generator Inventory | 1.5 MW solar | Under construction | LEAD #2 CA Bloomington 2551 S Lilac Avenue Micro | EIA-860M Preliminary Monthly Electric Generator Inventory | 1.5 MW storage | Under construction | unit of #1 (high) | H18: CA Bloomington 2551 S Lilac Avenue Micro 1.5 MW, solar, Under construction, US-CA | I18: 2 | J18: high | L18: Catalyze Bloomington 2551 S Lilac Avenue Microgrid LLC | M18: 66475 | N18: eia_plant/high | O18: 320 | P18: 45 | Q18: =IF(P18>0,O18/P18,"") -> 7.1111111 | R18: site_1M4KNFAFRENZA5XJ93XNWENGA | S18: us.eia.860m:66475-18263; us.eia.860m:66475-B8263
A19: S18 | B19: =HYPERLINK(BaseURL&"/sites/site_1M4KNFAFVF7BTY16QD7DW6BJ4","Zeta Solar & Storage") -> Zeta Solar & Storage | C19: Same EIA plant | D19: #1 Zeta Solar & Storage | EIA-860M Preliminary Monthly Electric Generator Inventory | 75 MW solar | Under construction | LEAD #2 Zeta Solar & Storage | EIA-860M Preliminary Monthly Electric Generator Inventory | 75 MW storage | Under construction | unit of #1 (high) | H19: Zeta Solar & Storage 75 MW, solar, Under construction, US-CA | I19: 2 | J19: high | L19: Zeta Solar, LLC | M19: 67676 | N19: eia_plant/high | O19: 320 | P19: 45 | Q19: =IF(P19>0,O19/P19,"") -> 7.1111111 | R19: site_1M4KNFAFVF7BTY16QD7DW6BJ4 | S19: us.eia.860m:67676-GEN01; us.eia.860m:67676-GEN02
A20: S19 | B20: =HYPERLINK(BaseURL&"/sites/site_1M4KNFAG3FMA95SF3DECWEEAX","Robeson Solar I") -> Robeson Solar I | C20: Same EIA plant | D20: #1 Robeson Solar I | EIA-860M Preliminary Monthly Electric Generator Inventory | 80 MW solar | Announced | LEAD #2 Robeson Solar I | EIA-860M Preliminary Monthly Electric Generator Inventory | 28 MW storage | Announced | unit of #1 (high) | H20: Robeson Solar I 80 MW, solar, Announced, US-NC | I20: 2 | J20: high | L20: AES Clean Energy | M20: 68043 | N20: eia_plant/high | O20: 320 | P20: 45 | Q20: =IF(P20>0,O20/P20,"") -> 7.1111111 | R20: site_1M4KNFAG3FMA95SF3DECWEEAX | S20: us.eia.860m:68043-ROBES; us.eia.860m:68043-ROBSS
A21: S20 | B21: =HYPERLINK(BaseURL&"/sites/site_1M4KNFAG2ENV8VX9EWNYB44GS","NISA Electric Generation Project") -> NISA Electric Generation Project | C21: Same EIA plant | D21: #1 NISA Electric Generation Project | EIA-860M Preliminary Monthly Electric Generator Inventory | 220.1 MW storage | Permitted | LEAD #2 NISA Electric Generation Project | EIA-860M Preliminary Monthly Electric Generator Inventory | 79.9 MW storage | Permitted | unit of #1 (high) | H21: NISA Electric Generation Project 220.1 MW, storage, Permitted, US-NY | I21: 2 | J21: high | L21: NYC Energy LLC | M21: 61331 | N21: eia_plant/high | O21: 320 | P21: 45 | Q21: =IF(P21>0,O21/P21,"") -> 7.1111111 | R21: site_1M4KNFAG2ENV8VX9EWNYB44GS | S21: us.eia.860m:61331-BA2; us.eia.860m:61331-BA1
A22: S21 | B22: =HYPERLINK(BaseURL&"/sites/site_1M4KNFAFPEK6RXR1TGYBDWQ35","Pacifico Power Lancaster 01") -> Pacifico Power Lancaster 01 | C22: Same EIA plant | D22: #1 Pacifico Power Lancaster 01 | EIA-860M Preliminary Monthly Electric Generator Inventory | 5.9 MW solar | Under construction | LEAD #2 Pacifico Power Lancaster 01 | EIA-860M Preliminary Monthly Electric Generator Inventory | 0.5 MW storage | Under construction | unit of #1 (high) | H22: Pacifico Power Lancaster 01 5.9 MW, solar, Under construction, US-CA | I22: 2 | J22: high | L22: Pacifico Power Lancaster 01 LLC | M22: 70388 | N22: eia_plant/high | O22: 320 | P22: 45 | Q22: =IF(P22>0,O22/P22,"") -> 7.1111111 | R22: site_1M4KNFAFPEK6RXR1TGYBDWQ35 | S22: us.eia.860m:70388-LANS; us.eia.860m:70388-LANB
A23: S22 | B23: =HYPERLINK(BaseURL&"/sites/site_1M4KNFAG1EEQR9E66CDYEJCD2","Alina Energy LLC") -> Alina Energy LLC | C23: Same EIA plant | D23: #1 Alina Energy LLC | EIA-860M Preliminary Monthly Electric Generator Inventory | 200 MW solar | Announced | LEAD #2 Alina Energy LLC | EIA-860M Preliminary Monthly Electric Generator Inventory | 200 MW storage | Announced | unit of #1 (high) | H23: Alina Energy LLC 200 MW, solar, Announced, US-TX | I23: 2 | J23: high | L23: Alina Energy LLC | M23: 67250 | N23: eia_plant/high | O23: 320 | P23: 45 | Q23: =IF(P23>0,O23/P23,"") -> 7.1111111 | R23: site_1M4KNFAG1EEQR9E66CDYEJCD2 | S23: us.eia.860m:67250-ALIPV; us.eia.860m:67250-ALIBS
A24: S23 | B24: =HYPERLINK(BaseURL&"/sites/site_1M4KNFAFTEKZRSJ3K634H3MJY","Vast Sands Power") -> Vast Sands Power | C24: Same EIA plant | D24: #1 Vast Sands Power | EIA-860M Preliminary Monthly Electric Generator Inventory | 440 MW gas, combustion turbine | Under construction | LEAD #2 Vast Sands Power | EIA-860M Preliminary Monthly Electric Generator Inventory | 440 MW gas, combustion turbine | Under construction | unit of #1 (high) | H24: Vast Sands Power 440 MW, gas, combustion turbine, Under construction, US-TX | I24: 2 | J24: high | L24: Permian Power I LLC | M24: 69689 | N24: eia_plant/high | O24: 320 | P24: 45 | Q24: =IF(P24>0,O24/P24,"") -> 7.1111111 | R24: site_1M4KNFAFTEKZRSJ3K634H3MJY | S24: us.eia.860m:69689-CT11; us.eia.860m:69689-CT12
A25: S24 | B25: =HYPERLINK(BaseURL&"/sites/site_1M4KNFAG0EDM8VBEGZRV9Z29Q","Rawhide") -> Rawhide | C25: Same EIA plant | D25: #1 Rawhide | EIA-860M Preliminary Monthly Electric Generator Inventory | 44.6 MW gas, combustion turbine | Announced | LEAD #2 Rawhide | EIA-860M Preliminary Monthly Electric Generator Inventory | 44.6 MW gas, combustion turbine | Announced | unit of #1 (high) #3 Rawhide | EIA-860M Preliminary Monthly Electric Generator Inventory | 44.6 MW gas, combustion turbine | Announced | unit of #1 (high) ... and 2 more units of EIA plant 6761 (unit of #1, high): 44.6 MW to 44.6 MW, Announced; all listed on 'Site members' | H25: Rawhide 44.6 MW, gas, combustion turbine, Announced, US-CO | I25: 5 | J25: high | L25: Platte River Power Authority | M25: 6761 | N25: eia_plant/high | O25: 320 | P25: 45 | Q25: =IF(P25>0,O25/P25,"") -> 7.1111111 | R25: site_1M4KNFAG0EDM8VBEGZRV9Z29Q | S25: us.eia.860m:6761-H; us.eia.860m:6761-G; us.eia.860m:6761-LM5; us.eia.860m:6761-LM4; us.eia.860m:6761-LM3
A26: S25 | B26: =HYPERLINK(BaseURL&"/sites/site_1M4KNFAFVF6YTJCBAW9C92DBG","Cherry") -> Cherry | C26: Same EIA plant | D26: #1 Cherry | EIA-860M Preliminary Monthly Electric Generator Inventory | 249.7 MW solar | Permitted | LEAD #2 Cherry | EIA-860M Preliminary Monthly Electric Generator Inventory | 110 MW storage | Permitted | unit of #1 (high) | H26: Cherry 249.7 MW, solar, Permitted, US-CA | I26: 2 | J26: high | L26: Westlands Cherry, LLC | M26: 63850 | N26: eia_plant/high | O26: 320 | P26: 45 | Q26: =IF(P26>0,O26/P26,"") -> 7.1111111 | R26: site_1M4KNFAFVF6YTJCBAW9C92DBG | S26: us.eia.860m:63850-CHERY; us.eia.860m:63850-BESS2
A27: S26 | B27: =HYPERLINK(BaseURL&"/sites/site_1M4KNFAFZFJ989W6JH7CAZES1","Vichy Solar") -> Vichy Solar | C27: Same EIA plant | D27: #1 Vichy Solar | EIA-860M Preliminary Monthly Electric Generator Inventory | 200 MW storage | Announced | LEAD #2 Vichy Solar | EIA-860M Preliminary Monthly Electric Generator Inventory | 200 MW solar | Announced | unit of #1 (high) | H27: Vichy Solar 200 MW, storage, Announced, US-MO | I27: 2 | J27: high | L27: Vesper Energy Development LLC | M27: 68036 | N27: eia_plant/high | O27: 320 | P27: 45 | Q27: =IF(P27>0,O27/P27,"") -> 7.1111111 | R27: site_1M4KNFAFZFJ989W6JH7CAZES1 | S27: us.eia.860m:68036-VCHSB; us.eia.860m:68036-VCHSR
A28: S27 | B28: =HYPERLINK(BaseURL&"/sites/site_1M4KNFAG5EKX83N3KD7MPSXRD","Solstice Solar LLC") -> Solstice Solar LLC | C28: Same EIA plant | D28: #1 Solstice Solar LLC | EIA-860M Preliminary Monthly Electric Generator Inventory | 200 MW storage | Announced | LEAD #2 Solstice Solar LLC | EIA-860M Preliminary Monthly Electric Generator Inventory | 200 MW solar | Announced | unit of #1 (high) | H28: Solstice Solar LLC 200 MW, storage, Announced, US-OK | I28: 2 | J28: high | L28: Clenera DevCo LLC | M28: 70186 | N28: eia_plant/high | O28: 320 | P28: 45 | Q28: =IF(P28>0,O28/P28,"") -> 7.1111111 | R28: site_1M4KNFAG5EKX83N3KD7MPSXRD | S28: us.eia.860m:70186-SOLBS; us.eia.860m:70186-SOLPV
A29: S28 | B29: =HYPERLINK(BaseURL&"/sites/site_1M4KNFAG0EW3RMQP83H2R6X48","Hornet Solar II (TX) (Hybrid)") -> Hornet Solar II (TX) (Hybrid) | C29: Same EIA plant | D29: #1 Hornet Solar II (TX) (Hybrid) | EIA-860M Preliminary Monthly Electric Generator Inventory | 200 MW solar | Filed | LEAD #2 Hornet Solar II (TX) (Hybrid) | EIA-860M Preliminary Monthly Electric Generator Inventory | 200 MW storage | Filed | unit of #1 (high) | H29: Hornet Solar II (TX) (Hybrid) 200 MW, solar, Filed, US-TX | I29: 2 | J29: high | L29: Vesper Energy Development LLC | M29: 67985 | N29: eia_plant/high | O29: 320 | P29: 45 | Q29: =IF(P29>0,O29/P29,"") -> 7.1111111 | R29: site_1M4KNFAG0EW3RMQP83H2R6X48 | S29: us.eia.860m:67985-HRNT2; us.eia.860m:67985-HRT2B
A30: S29 | B30: =HYPERLINK(BaseURL&"/sites/site_1M4KNFAFVE14B58HE94MDVTFD","Four Mile Mesa Solar, LLC") -> Four Mile Mesa Solar, LLC | C30: Same EIA plant | D30: #1 Four Mile Mesa Solar, LLC | EIA-860M Preliminary Monthly Electric Generator Inventory | 100 MW solar | Under construction | LEAD #2 Four Mile Mesa Solar, LLC | EIA-860M Preliminary Monthly Electric Generator Inventory | 100 MW storage | Under construction | unit of #1 (high) | H30: Four Mile Mesa Solar, LLC 100 MW, solar, Under construction, US-NM | I30: 2 | J30: high | L30: Four Mile Mesa Solar, LLC | M30: 69966 | N30: eia_plant/high | O30: 320 | P30: 45 | Q30: =IF(P30>0,O30/P30,"") -> 7.1111111 | R30: site_1M4KNFAFVE14B58HE94MDVTFD | S30: us.eia.860m:69966-FMM; us.eia.860m:69966-FMMS
A31: S30 | B31: =HYPERLINK(BaseURL&"/sites/site_1M4KNFAG1FKHVMRV8TTBMSFF6","CO Bar D Solar and BESS") -> CO Bar D Solar and BESS | C31: Same EIA plant | D31: #1 CO Bar D Solar and BESS | EIA-860M Preliminary Monthly Electric Generator Inventory | 394 MW storage | Announced | LEAD #2 CO Bar D Solar and BESS | EIA-860M Preliminary Monthly Electric Generator Inventory | 394 MW solar | Announced | unit of #1 (high) | H31: CO Bar D Solar and BESS 394 MW, storage, Announced, US-AZ | I31: 2 | J31: high | L31: Clenera DevCo LLC | M31: 69057 | N31: eia_plant/high | O31: 320 | P31: 45 | Q31: =IF(P31>0,O31/P31,"") -> 7.1111111 | R31: site_1M4KNFAG1FKHVMRV8TTBMSFF6 | S31: us.eia.860m:69057-CBDBA; us.eia.860m:69057-CBDPV
A32: S31 | B32: =HYPERLINK(BaseURL&"/sites/site_1M4KNFAFVE6TVXF2YGFKS5TMM","Bishop Ranch - BR 3-GG") -> Bishop Ranch - BR 3-GG | C32: Same EIA plant | D32: #1 Bishop Ranch - BR 3-GG | EIA-860M Preliminary Monthly Electric Generator Inventory | 1.1 MW solar | Under construction | LEAD #2 Bishop Ranch - BR 3-GG | EIA-860M Preliminary Monthly Electric Generator Inventory | 0.6 MW storage | Under construction | unit of #1 (high) #3 Bishop Ranch - BR 3-GG | EIA-860M Preliminary Monthly Electric Generator Inventory | 0.2 MW solar | Under construction | unit of #1 (high) | H32: Bishop Ranch - BR 3-GG 1.1 MW, solar, Under construction, US-CA | I32: 3 | J32: high | L32: Camino Ramon BR 3-GG Solar Project 2020, LLC | M32: 69706 | N32: eia_plant/high | O32: 320 | P32: 45 | Q32: =IF(P32>0,O32/P32,"") -> 7.1111111 | R32: site_1M4KNFAFVE6TVXF2YGFKS5TMM | S32: us.eia.860m:69706-4149C; us.eia.860m:69706-4149B; us.eia.860m:69706-4149R
A33: S32 | B33: =HYPERLINK(BaseURL&"/sites/site_1M4KNFAG3E82TWB9P9RW44Y8M","Sienna Solar Farm") -> Sienna Solar Farm | C33: Same EIA plant | D33: #1 Sienna Solar Farm | EIA-860M Preliminary Monthly Electric Generator Inventory | 200 MW solar | Announced | LEAD #2 Sienna Solar Farm | EIA-860M Preliminary Monthly Electric Generator Inventory | 200 MW storage | Announced | unit of #1 (high) | H33: Sienna Solar Farm 200 MW, solar, Announced, US-CA | I33: 2 | J33: high | L33: 99MT 8me, LLC | M33: 64632 | N33: eia_plant/high | O33: 320 | P33: 45 | Q33: =IF(P33>0,O33/P33,"") -> 7.1111111 | R33: site_1M4KNFAG3E82TWB9P9RW44Y8M | S33: us.eia.860m:64632-99MT8; us.eia.860m:64632-99MTB
A34: S33 | B34: =HYPERLINK(BaseURL&"/sites/site_1M4KNFAFSF08STX9TV1NR3TTN","FRP Miller Solar") -> FRP Miller Solar | C34: Same EIA plant | D34: #1 FRP Miller Solar | EIA-860M Preliminary Monthly Electric Generator Inventory | 74.5 MW solar | Under construction | LEAD #2 FRP Miller Solar | EIA-860M Preliminary Monthly Electric Generator Inventory | 50 MW storage | Under construction | unit of #1 (high) | H34: FRP Miller Solar 74.5 MW, solar, Under construction, US-FL | I34: 2 | J34: high | L34: FRP Miller Solar LLC | M34: 69626 | N34: eia_plant/high | O34: 320 | P34: 45 | Q34: =IF(P34>0,O34/P34,"") -> 7.1111111 | R34: site_1M4KNFAFSF08STX9TV1NR3TTN | S34: us.eia.860m:69626-SMF; us.eia.860m:69626-BMF
A35: S34 | B35: =HYPERLINK(BaseURL&"/sites/site_1M4KNFAFSFCJRMJYJJAGP9ZAG","Clear Fork Creek Solar and BESS SLF") -> Clear Fork Creek Solar and BESS SLF | C35: Same EIA plant | D35: #1 Clear Fork Creek Solar and BESS SLF | EIA-860M Preliminary Monthly Electric Generator Inventory | 600 MW storage | Under construction | LEAD #2 Clear Fork Creek Solar and BESS SLF | EIA-860M Preliminary Monthly Electric Generator Inventory | 600 MW solar | Under construction | unit of #1 (high) | H35: Clear Fork Creek Solar and BESS SLF 600 MW, storage, Under construction, US-TX | I35: 2 | J35: high | L35: Clear Fork | M35: 65842 | N35: eia_plant/high | O35: 320 | P35: 45 | Q35: =IF(P35>0,O35/P35,"") -> 7.1111111 | R35: site_1M4KNFAFSFCJRMJYJJAGP9ZAG | S35: us.eia.860m:65842-CFCBS; us.eia.860m:65842-CFCPV
A36: S35 | B36: =HYPERLINK(BaseURL&"/sites/site_1M4KNFAG3EVKBABJP1Y174S1R","Cuchillas PV and BESS") -> Cuchillas PV and BESS | C36: Same EIA plant | D36: #1 Cuchillas PV and BESS | EIA-860M Preliminary Monthly Electric Generator Inventory | 306.9 MW storage | Filed | LEAD #2 Cuchillas PV and BESS | EIA-860M Preliminary Monthly Electric Generator Inventory | 305.6 MW solar | Filed | unit of #1 (high) | H36: Cuchillas PV and BESS 306.9 MW, storage, Filed, US-TX | I36: 2 | J36: high | L36: Gransolar Texas Two, LLC | M36: 67776 | N36: eia_plant/high | O36: 320 | P36: 45 | Q36: =IF(P36>0,O36/P36,"") -> 7.1111111 | R36: site_1M4KNFAG3EVKBABJP1Y174S1R | S36: us.eia.860m:67776-GRS2B; us.eia.860m:67776-GRS2P
A37: S36 | B37: =HYPERLINK(BaseURL&"/sites/site_1M4KNFAG5FMWS7JZCVK6N6K5E","Grand Valley Solar Generation and BESS") -> Grand Valley Solar Generation and BESS | C37: Same EIA plant | D37: #1 Grand Valley Solar Generation and BESS | EIA-860M Preliminary Monthly Electric Generator Inventory | 100 MW solar | Filed | LEAD #2 Grand Valley Solar Generation and BESS | EIA-860M Preliminary Monthly Electric Generator Inventory | 100 MW storage | Filed | unit of #1 (high) | H37: Grand Valley Solar Generation and BESS 100 MW, solar, Filed, US-CO | I37: 2 | J37: high | L37: GRVA bn, LLC | M37: 68343 | N37: eia_plant/high | O37: 320 | P37: 45 | Q37: =IF(P37>0,O37/P37,"") -> 7.1111111 | R37: site_1M4KNFAG5FMWS7JZCVK6N6K5E | S37: us.eia.860m:68343-GRVA1; us.eia.860m:68343-GRVA2
A38: S37 | B38: =HYPERLINK(BaseURL&"/sites/site_1M4KNFAG5FN1RMNMRWEXH5MD1","Sacramento Valley Energy Center, LLC") -> Sacramento Valley Energy Center, LLC | C38: Same EIA plant | D38: #1 Sacramento Valley Energy Center, LLC | EIA-860M Preliminary Monthly Electric Generator Inventory | 200 MW solar | Under construction | LEAD #2 Sacramento Valley Energy Center, LLC | EIA-860M Preliminary Monthly Electric Generator Inventory | 100 MW storage | Under construction | unit of #1 (high) | H38: Sacramento Valley Energy Center, LLC 200 MW, solar, Under construction, US-CA | I38: 2 | J38: high | L38: Sacramento Valley Energy Center, LLC | M38: 65808 | N38: eia_plant/high | O38: 320 | P38: 45 | Q38: =IF(P38>0,O38/P38,"") -> 7.1111111 | R38: site_1M4KNFAG5FN1RMNMRWEXH5MD1 | S38: us.eia.860m:65808-SVEC; us.eia.860m:65808-BSVEC
A39: S38 | B39: =HYPERLINK(BaseURL&"/sites/site_1M4KNFAFWE1NT4WPZGYCZ9XN7","Fish Lake Geothermal") -> Fish Lake Geothermal | C39: Same EIA plant | D39: #1 Fish Lake Geothermal | EIA-860M Preliminary Monthly Electric Generator Inventory | 9 MW geothermal | Announced | LEAD #2 Fish Lake Geothermal | EIA-860M Preliminary Monthly Electric Generator Inventory | 6.2 MW geothermal | Announced | unit of #1 (high) #3 Fish Lake Geothermal | EIA-860M Preliminary Monthly Electric Generator Inventory | 4.7 MW geothermal | Announced | unit of #1 (high) ... and 2 more units of EIA plant 66618 (unit of #1, high): 3.3 MW to 3.3 MW, Announced; all listed on 'Site members' | H39: Fish Lake Geothermal 9 MW, geothermal, Announced, US-NV | I39: 5 | J39: high | L39: Fish Lake Geothermal LLC | M39: 66618 | N39: eia_plant/high | O39: 320 | P39: 45 | Q39: =IF(P39>0,O39/P39,"") -> 7.1111111 | R39: site_1M4KNFAFWE1NT4WPZGYCZ9XN7 | S39: us.eia.860m:66618-FL5; us.eia.860m:66618-FL4; us.eia.860m:66618-FL3; us.eia.860m:66618-FL1; us.eia.860m:66618-FL2
A40: S39 | B40: =HYPERLINK(BaseURL&"/sites/site_1M4KNFAFWE61858BBT5NQR2B0","Lupinus Solar 1, LLC") -> Lupinus Solar 1, LLC | C40: Same EIA plant | D40: #1 Lupinus Solar 1, LLC | EIA-860M Preliminary Monthly Electric Generator Inventory | 165 MW solar | Announced | LEAD #2 Lupinus Solar 1, LLC | EIA-860M Preliminary Monthly Electric Generator Inventory | 83 MW storage | Announced | unit of #1 (high) | H40: Lupinus Solar 1, LLC 165 MW, solar, Announced, US-TX | I40: 2 | J40: high | L40: Sunraycer Assets I LLC | M40: 66895 | N40: eia_plant/high | O40: 320 | P40: 45 | Q40: =IF(P40>0,O40/P40,"") -> 7.1111111 | R40: site_1M4KNFAFWE61858BBT5NQR2B0 | S40: us.eia.860m:66895-LP1PV; us.eia.860m:66895-LP1BA
...

Sheet Merged records
A1: Item | B1: Record | C1: As served | D1: Source links | E1: One real project? | F1: What kind | G1: Notes | H1: Links | I1: Registers | J1: EIA plant ids | K1: Category | L1: Also matches | M1: In site | N1: Stratum | O1: Stratum population | P1: Stratum sample | Q1: Weight | R1: Record id (this store) | S1: Link keys (stable)

Sheet Site members
A1: Item | B1: Site | C1: # | D1: Member | E1: Relation | F1: Confidence | G1: Relation rule | H1: Grouped by | I1: Sources | J1: MW | K1: Technology | L1: Status | M1: Jurisdiction | N1: Sponsor | O1: Connection point | P1: EIA plant ids | Q1: Record id (this store) | R1: Link keys (stable)
A2: S01 | B2: Hashknife Energy Center II LLC | C2: 1 | D2: =HYPERLINK(BaseURL&"/proposals/hashknife-energy-center-ii-llc-1v6cp4","Hashknife Energy Center II LLC") -> Hashknife Energy Center II LLC | E2: LEAD | F2: high | G2: largest_active_then_latest | H2: Same EIA plant | I2: EIA-860M Preliminary Monthly Electric Generator Inventory | J2: 200 MW | K2: storage | L2: Under construction | M2: US-AZ | N2: Invenergy Services LLC | P2: 69779 | Q2: prop_1M4HNHZN9EK6RSDGGCN1V6CP4 | R2: us.eia.860m:69779-HK2ST
A3: S01 | B3: Hashknife Energy Center II LLC | C3: 2 | D3: =HYPERLINK(BaseURL&"/proposals/hashknife-energy-center-ii-llc-6n3mg5","Hashknife Energy Center II LLC") -> Hashknife Energy Center II LLC | E3: unit of #1 | F3: high | G3: shared_eia_plant | H3: Same EIA plant | I3: EIA-860M Preliminary Monthly Electric Generator Inventory | J3: 200 MW | K3: solar | L3: Under construction | M3: US-AZ | N3: Invenergy Services LLC | P3: 69779 | Q3: prop_1M4HNHZN9FS1B0SS1X96N3MG5 | R3: us.eia.860m:69779-HK2SO
A4: S02 | B4: Rexford 2 Solar Farm | C4: 1 | D4: =HYPERLINK(BaseURL&"/proposals/rexford-2-solar-farm-mz0sw0","Rexford 2 Solar Farm") -> Rexford 2 Solar Farm | E4: LEAD | F4: high | G4: largest_active_then_latest | H4: Same EIA plant | I4: EIA-860M Preliminary Monthly Electric Generator Inventory | J4: 200 MW | K4: solar | L4: Announced | M4: US-CA | N4: 22SV 8ME LLC | P4: 68485 | Q4: prop_1M4HNJ168EYXBVVVFAQMZ0SW0 | R4: us.eia.860m:68485-22SVA
A5: S02 | B5: Rexford 2 Solar Farm | C5: 2 | D5: =HYPERLINK(BaseURL&"/proposals/rexford-2-solar-farm-1cqke0","Rexford 2 Solar Farm") -> Rexford 2 Solar Farm | E5: unit of #1 | F5: high | G5: shared_eia_plant | H5: Same EIA plant | I5: EIA-860M Preliminary Monthly Electric Generator Inventory | J5: 200 MW | K5: storage | L5: Announced | M5: US-CA | N5: 22SV 8ME LLC | P5: 68485 | Q5: prop_1M4HNJ168EZZRK9DXCB1CQKE0 | R5: us.eia.860m:68485-22SVB
A6: S03 | B6: Harryoung PV and BESS | C6: 1 | D6: =HYPERLINK(BaseURL&"/proposals/harryoung-pv-and-bess-31rtw6","Harryoung PV and BESS") -> Harryoung PV and BESS | E6: LEAD | F6: high | G6: largest_active_then_latest | H6: Same EIA plant | I6: EIA-860M Preliminary Monthly Electric Generator Inventory | J6: 190 MW | K6: storage | L6: Filed | M6: US-TX | N6: Gransolar Texas Four LLC | P6: 67777 | Q6: prop_1M4HNJ11DE308PQCSCN31RTW6 | R6: us.eia.860m:67777-GRS4B
A7: S03 | B7: Harryoung PV and BESS | C7: 2 | D7: =HYPERLINK(BaseURL&"/proposals/harryoung-pv-and-bess-jd65gq","Harryoung PV and BESS") -> Harryoung PV and BESS | E7: unit of #1 | F7: high | G7: shared_eia_plant | H7: Same EIA plant | I7: EIA-860M Preliminary Monthly Electric Generator Inventory | J7: 190 MW | K7: solar | L7: Filed | M7: US-TX | N7: Gransolar Texas Four LLC | P7: 67777 | Q7: prop_1M4HNJ11EEWRTRZFHM1JD65GQ | R7: us.eia.860m:67777-GRS4P
A8: S04 | B8: Energy Center | C8: 1 | D8: =HYPERLINK(BaseURL&"/proposals/energy-center-hxtasw","Energy Center") -> Energy Center | E8: LEAD | F8: high | G8: largest_active_then_latest | H8: Same EIA plant | I8: EIA-860M Preliminary Monthly Electric Generator Inventory | J8: 0.3 MW | K8: gas, combustion turbine | L8: Announced | M8: US-CA | N8: University of Redlands | P8: 58168 | Q8: prop_1M4HNJ1R3FCHAM5DSHAHXTASW | R8: us.eia.860m:58168-TURB4
A9: S04 | B9: Energy Center | C9: 2 | D9: =HYPERLINK(BaseURL&"/proposals/energy-center-hbs6sh","Energy Center") -> Energy Center | E9: unit of #1 | F9: high | G9: shared_eia_plant | H9: Same EIA plant | I9: EIA-860M Preliminary Monthly Electric Generator Inventory | J9: 0.3 MW | K9: gas, combustion turbine | L9: Announced | M9: US-CA | N9: University of Redlands | P9: 58168 | Q9: prop_1M4HNJ1R4EDHV6FRQSGHBS6SH | R9: us.eia.860m:58168-TURB6
A10: S04 | B10: Energy Center | C10: 3 | D10: =HYPERLINK(BaseURL&"/proposals/energy-center-11vh3r","Energy Center") -> Energy Center | E10: unit of #1 | F10: high | G10: shared_eia_plant | H10: Same EIA plant | I10: EIA-860M Preliminary Monthly Electric Generator Inventory | J10: 0.3 MW | K10: gas, combustion turbine | L10: Announced | M10: US-CA | N10: University of Redlands | P10: 58168 | Q10: prop_1M4HNJ1R4FKBTY6BYJN11VH3R | R10: us.eia.860m:58168-TURB5
A11: S05 | B11: Snipatuit Road Solar | C11: 1 | D11: =HYPERLINK(BaseURL&"/proposals/snipatuit-road-solar-x95nxq","Snipatuit Road Solar") -> Snipatuit Road Solar | E11: LEAD | F11: high | G11: largest_active_then_latest | H11: Same EIA plant | I11: EIA-860M Preliminary Monthly Electric Generator Inventory | J11: 4 MW | K11: storage | L11: Filed | M11: US-MA | N11: Agilitas Energy, Inc. | P11: 68219 | Q11: prop_1M4HNHZN2FK29N4X8SVX95NXQ | R11: us.eia.860m:68219-SNIES
A12: S05 | B12: Snipatuit Road Solar | C12: 2 | D12: =HYPERLINK(BaseURL&"/proposals/snipatuit-road-solar-p0hmdb","Snipatuit Road Solar") -> Snipatuit Road Solar | E12: unit of #1 | F12: high | G12: shared_eia_plant | H12: Same EIA plant | I12: EIA-860M Preliminary Monthly Electric Generator Inventory | J12: 4 MW | K12: solar | L12: Filed | M12: US-MA | N12: Agilitas Energy, Inc. | P12: 68219 | Q12: prop_1M4HNHZN3FP4BVX6TQRP0HMDB | R12: us.eia.860m:68219-SNIPV
A13: S06 | B13: Libra Solar | C13: 1 | D13: =HYPERLINK(BaseURL&"/proposals/libra-solar-affan0","Libra Solar") -> Libra Solar | E13: LEAD | F13: high | G13: largest_active_then_latest | H13: Same EIA plant | I13: EIA-860M Preliminary Monthly Electric Generator Inventory | J13: 700 MW | K13: storage | L13: Under construction | M13: US-NV | N13: Libra Solar LLC | P13: 69857 | Q13: prop_1M4HNJ0AKERNBA4GX0FAFFAN0 | R13: us.eia.860m:69857-LBRBS
A14: S06 | B14: Libra Solar | C14: 2 | D14: =HYPERLINK(BaseURL&"/proposals/libra-solar-6p5p0f","Libra Solar") -> Libra Solar | E14: unit of #1 | F14: high | G14: shared_eia_plant | H14: Same EIA plant | I14: EIA-860M Preliminary Monthly Electric Generator Inventory | J14: 700 MW | K14: solar | L14: Under construction | M14: US-NV | N14: Libra Solar LLC | P14: 69857 | Q14: prop_1M4HNJ0AKFZYTVPX9F76P5P0F | R14: us.eia.860m:69857-LBRPV
A15: S07 | B15: Project Matador Gas Plant (PMG) | C15: 1 | D15: =HYPERLINK(BaseURL&"/proposals/project-matador-gas-plant-pmg-sh1kcw","Project Matador Gas Plant (PMG)") -> Project Matador Gas Plant (PMG) | E15: LEAD | F15: high | G15: largest_active_then_latest | H15: Same EIA plant | I15: EIA-860M Preliminary Monthly Electric Generator Inventory | J15: 260 MW | K15: gas, combined cycle | L15: Announced | M15: US-TX | N15: Fermi America | P15: 69799 | Q15: prop_1M4HNJ059FT8V26TS8BSH1KCW | R15: us.eia.860m:69799-F1G01
A16: S07 | B16: Project Matador Gas Plant (PMG) | C16: 2 | D16: =HYPERLINK(BaseURL&"/proposals/project-matador-gas-plant-pmg-z7qggn","Project Matador Gas Plant (PMG)") -> Project Matador Gas Plant (PMG) | E16: unit of #1 | F16: high | G16: shared_eia_plant | H16: Same EIA plant | I16: EIA-860M Preliminary Monthly Electric Generator Inventory | J16: 260 MW | K16: gas, combined cycle | L16: Announced | M16: US-TX | N16: Fermi America | P16: 69799 | Q16: prop_1M4HNJ05AEVG8JMP9WJZ7QGGN | R16: us.eia.860m:69799-F1G02
A17: S07 | B17: Project Matador Gas Plant (PMG) | C17: 3 | D17: =HYPERLINK(BaseURL&"/proposals/project-matador-gas-plant-pmg-rspaej","Project Matador Gas Plant (PMG)") -> Project Matador Gas Plant (PMG) | E17: unit of #1 | F17: high | G17: shared_eia_plant | H17: Same EIA plant | I17: EIA-860M Preliminary Monthly Electric Generator Inventory | J17: 260 MW | K17: gas, combined cycle | L17: Announced | M17: US-TX | N17: Fermi America | P17: 69799 | Q17: prop_1M4HNJ05AFJXRB152WSRSPAEJ | R17: us.eia.860m:69799-F1G03
A18: S07 | B18: Project Matador Gas Plant (PMG) | C18: 4 | D18: =HYPERLINK(BaseURL&"/proposals/project-matador-gas-plant-pmg-dkh7n0","Project Matador Gas Plant (PMG)") -> Project Matador Gas Plant (PMG) | E18: unit of #1 | F18: high | G18: shared_eia_plant | H18: Same EIA plant | I18: EIA-860M Preliminary Monthly Electric Generator Inventory | J18: 260 MW | K18: gas, combined cycle | L18: Announced | M18: US-TX | N18: Fermi America | P18: 69799 | Q18: prop_1M4HNJ05BF4NRV5RY3DDKH7N0 | R18: us.eia.860m:69799-F2G01
A19: S07 | B19: Project Matador Gas Plant (PMG) | C19: 5 | D19: =HYPERLINK(BaseURL&"/proposals/project-matador-gas-plant-pmg-r1pcen","Project Matador Gas Plant (PMG)") -> Project Matador Gas Plant (PMG) | E19: unit of #1 | F19: high | G19: shared_eia_plant | H19: Same EIA plant | I19: EIA-860M Preliminary Monthly Electric Generator Inventory | J19: 260 MW | K19: gas, combined cycle | L19: Announced | M19: US-TX | N19: Fermi America | P19: 69799 | Q19: prop_1M4HNJ05BFFNS6XH4T8R1PCEN | R19: us.eia.860m:69799-F2G02
A20: S07 | B20: Project Matador Gas Plant (PMG) | C20: 6 | D20: =HYPERLINK(BaseURL&"/proposals/project-matador-gas-plant-pmg-jwz1ck","Project Matador Gas Plant (PMG)") -> Project Matador Gas Plant (PMG) | E20: unit of #1 | F20: high | G20: shared_eia_plant | H20: Same EIA plant | I20: EIA-860M Preliminary Monthly Electric Generator Inventory | J20: 260 MW | K20: gas, combined cycle | L20: Announced | M20: US-TX | N20: Fermi America | P20: 69799 | Q20: prop_1M4HNJ05CFJ19ZA4JKMJWZ1CK | R20: us.eia.860m:69799-F2G03
A21: S07 | B21: Project Matador Gas Plant (PMG) | C21: 7 | D21: =HYPERLINK(BaseURL&"/proposals/project-matador-gas-plant-pmg-px3jc2","Project Matador Gas Plant (PMG)") -> Project Matador Gas Plant (PMG) | E21: unit of #1 | F21: high | G21: shared_eia_plant | H21: Same EIA plant | I21: EIA-860M Preliminary Monthly Electric Generator Inventory | J21: 105 MW | K21: gas, combined cycle | L21: Announced | M21: US-TX | N21: Fermi America | P21: 69799 | Q21: prop_1M4HNJ0AGEWAA5TQJENPX3JC2 | R21: us.eia.860m:69799-F1S02
A22: S07 | B22: Project Matador Gas Plant (PMG) | C22: 8 | D22: =HYPERLINK(BaseURL&"/proposals/project-matador-gas-plant-pmg-bwdv31","Project Matador Gas Plant (PMG)") -> Project Matador Gas Plant (PMG) | E22: unit of #1 | F22: high | G22: shared_eia_plant | H22: Same EIA plant | I22: EIA-860M Preliminary Monthly Electric Generator Inventory | J22: 105 MW | K22: gas, combined cycle | L22: Announced | M22: US-TX | N22: Fermi America | P22: 69799 | Q22: prop_1M4HNJ0AGFG7ATP3HVABWDV31 | R22: us.eia.860m:69799-F1S01
A23: S07 | B23: Project Matador Gas Plant (PMG) | C23: 9 | D23: =HYPERLINK(BaseURL&"/proposals/project-matador-gas-plant-pmg-gg6bz0","Project Matador Gas Plant (PMG)") -> Project Matador Gas Plant (PMG) | E23: unit of #1 | F23: high | G23: shared_eia_plant | H23: Same EIA plant | I23: EIA-860M Preliminary Monthly Electric Generator Inventory | J23: 105 MW | K23: gas, combined cycle | L23: Announced | M23: US-TX | N23: Fermi America | P23: 69799 | Q23: prop_1M4HNJ0AHEAWRKVNJXNGG6BZ0 | R23: us.eia.860m:69799-F1S03
A24: S07 | B24: Project Matador Gas Plant (PMG) | C24: 10 | D24: =HYPERLINK(BaseURL&"/proposals/project-matador-gas-plant-pmg-dks90f","Project Matador Gas Plant (PMG)") -> Project Matador Gas Plant (PMG) | E24: unit of #1 | F24: high | G24: shared_eia_plant | H24: Same EIA plant | I24: EIA-860M Preliminary Monthly Electric Generator Inventory | J24: 105 MW | K24: gas, combined cycle | L24: Announced | M24: US-TX | N24: Fermi America | P24: 69799 | Q24: prop_1M4HNJ0AHEZXST66HPFDKS90F | R24: us.eia.860m:69799-F2S02
A25: S07 | B25: Project Matador Gas Plant (PMG) | C25: 11 | D25: =HYPERLINK(BaseURL&"/proposals/project-matador-gas-plant-pmg-kxwt3r","Project Matador Gas Plant (PMG)") -> Project Matador Gas Plant (PMG) | E25: unit of #1 | F25: high | G25: shared_eia_plant | H25: Same EIA plant | I25: EIA-860M Preliminary Monthly Electric Generator Inventory | J25: 105 MW | K25: gas, combined cycle | L25: Announced | M25: US-TX | N25: Fermi America | P25: 69799 | Q25: prop_1M4HNJ0AHFGAVCKZ3BVKXWT3R | R25: us.eia.860m:69799-F2S01
A26: S07 | B26: Project Matador Gas Plant (PMG) | C26: 12 | D26: =HYPERLINK(BaseURL&"/proposals/project-matador-gas-plant-pmg-n491nt","Project Matador Gas Plant (PMG)") -> Project Matador Gas Plant (PMG) | E26: unit of #1 | F26: high | G26: shared_eia_plant | H26: Same EIA plant | I26: EIA-860M Preliminary Monthly Electric Generator Inventory | J26: 105 MW | K26: gas, combined cycle | L26: Announced | M26: US-TX | N26: Fermi America | P26: 69799 | Q26: prop_1M4HNJ0AJF88V9MC3WCN491NT | R26: us.eia.860m:69799-F2S03
A27: S07 | B27: Project Matador Gas Plant (PMG) | C27: 13 | D27: =HYPERLINK(BaseURL&"/proposals/project-matador-gas-plant-pmg-nm2k4d","Project Matador Gas Plant (PMG)") -> Project Matador Gas Plant (PMG) | E27: unit of #1 | F27: high | G27: shared_eia_plant | H27: Same EIA plant | I27: EIA-860M Preliminary Monthly Electric Generator Inventory | J27: 105 MW | K27: gas, combined cycle | L27: Announced | M27: US-TX | N27: Fermi America | P27: 69799 | Q27: prop_1M4HNJ0AJFPHBR51GHSNM2K4D | R27: us.eia.860m:69799-FBS01
A28: S07 | B28: Project Matador Gas Plant (PMG) | C28: 14 | D28: =HYPERLINK(BaseURL&"/proposals/project-matador-gas-plant-pmg-87259f","Project Matador Gas Plant (PMG)") -> Project Matador Gas Plant (PMG) | E28: unit of #1 | F28: high | G28: shared_eia_plant | H28: Same EIA plant | I28: EIA-860M Preliminary Monthly Electric Generator Inventory | J28: 105 MW | K28: gas, combined cycle | L28: Announced | M28: US-TX | N28: Fermi America | P28: 69799 | Q28: prop_1M4HNJ1SJE09T2G6CDJ87259F | R28: us.eia.860m:69799-ES001
A29: S07 | B29: Project Matador Gas Plant (PMG) | C29: 15 | D29: =HYPERLINK(BaseURL&"/proposals/project-matador-gas-plant-pmg-yay2k9","Project Matador Gas Plant (PMG)") -> Project Matador Gas Plant (PMG) | E29: unit of #1 | F29: high | G29: shared_eia_plant | H29: Same EIA plant | I29: EIA-860M Preliminary Monthly Electric Generator Inventory | J29: 105 MW | K29: gas, combined cycle | L29: Announced | M29: US-TX | N29: Fermi America | P29: 69799 | Q29: prop_1M4HNJ1SJEVYBFXC2S7YAY2K9 | R29: us.eia.860m:69799-ES002
A30: S07 | B30: Project Matador Gas Plant (PMG) | C30: 16 | D30: =HYPERLINK(BaseURL&"/proposals/project-matador-gas-plant-pmg-01t0rg","Project Matador Gas Plant (PMG)") -> Project Matador Gas Plant (PMG) | E30: unit of #1 | F30: high | G30: shared_eia_plant | H30: Same EIA plant | I30: EIA-860M Preliminary Monthly Electric Generator Inventory | J30: 105 MW | K30: gas, combined cycle | L30: Announced | M30: US-TX | N30: Fermi America | P30: 69799 | Q30: prop_1M4HNJ1SKEP0963EH6P01T0RG | R30: us.eia.860m:69799-ES003
A31: S07 | B31: Project Matador Gas Plant (PMG) | C31: 17 | D31: =HYPERLINK(BaseURL&"/proposals/project-matador-gas-plant-pmg-he8gm6","Project Matador Gas Plant (PMG)") -> Project Matador Gas Plant (PMG) | E31: unit of #1 | F31: high | G31: shared_eia_plant | H31: Same EIA plant | I31: EIA-860M Preliminary Monthly Electric Generator Inventory | J31: 105 MW | K31: gas, combined cycle | L31: Announced | M31: US-TX | N31: Fermi America | P31: 69799 | Q31: prop_1M4HNJ1SKEYXRAB2DAJHE8GM6 | R31: us.eia.860m:69799-ES004
A32: S07 | B32: Project Matador Gas Plant (PMG) | C32: 18 | D32: =HYPERLINK(BaseURL&"/proposals/project-matador-gas-plant-pmg-z0aqwf","Project Matador Gas Plant (PMG)") -> Project Matador Gas Plant (PMG) | E32: unit of #1 | F32: high | G32: shared_eia_plant | H32: Same EIA plant | I32: EIA-860M Preliminary Monthly Electric Generator Inventory | J32: 105 MW | K32: gas, combined cycle | L32: Announced | M32: US-TX | N32: Fermi America | P32: 69799 | Q32: prop_1M4HNJ1SMFEAR0ZNVTQZ0AQWF | R32: us.eia.860m:69799-ES005
A33: S07 | B33: Project Matador Gas Plant (PMG) | C33: 19 | D33: =HYPERLINK(BaseURL&"/proposals/project-matador-gas-plant-pmg-xvqqb3","Project Matador Gas Plant (PMG)") -> Project Matador Gas Plant (PMG) | E33: unit of #1 | F33: high | G33: shared_eia_plant | H33: Same EIA plant | I33: EIA-860M Preliminary Monthly Electric Generator Inventory | J33: 105 MW | K33: gas, combined cycle | L33: Announced | M33: US-TX | N33: Fermi America | P33: 69799 | Q33: prop_1M4HNJ1SMFG2SB47CJXXVQQB3 | R33: us.eia.860m:69799-ES006
A34: S07 | B34: Project Matador Gas Plant (PMG) | C34: 20 | D34: =HYPERLINK(BaseURL&"/proposals/project-matador-gas-plant-pmg-t629a8","Project Matador Gas Plant (PMG)") -> Project Matador Gas Plant (PMG) | E34: unit of #1 | F34: high | G34: shared_eia_plant | H34: Same EIA plant | I34: EIA-860M Preliminary Monthly Electric Generator Inventory | J34: 105 MW | K34: gas, combined cycle | L34: Announced | M34: US-TX | N34: Fermi America | P34: 69799 | Q34: prop_1M4HNJ1SNEMNTREPSYYT629A8 | R34: us.eia.860m:69799-ES008
A35: S07 | B35: Project Matador Gas Plant (PMG) | C35: 21 | D35: =HYPERLINK(BaseURL&"/proposals/project-matador-gas-plant-pmg-5bc8wg","Project Matador Gas Plant (PMG)") -> Project Matador Gas Plant (PMG) | E35: unit of #1 | F35: high | G35: shared_eia_plant | H35: Same EIA plant | I35: EIA-860M Preliminary Monthly Electric Generator Inventory | J35: 105 MW | K35: gas, combined cycle | L35: Announced | M35: US-TX | N35: Fermi America | P35: 69799 | Q35: prop_1M4HNJ1SNF4PTWN8Y8X5BC8WG | R35: us.eia.860m:69799-ES007
